Workbook

Sheet Summary
A1: Hisab-Kitab AI — Testing Report v2: Employee, Customer, Supplier, Expense, Family, Stock, Purchase, Report, Correction, Router (before vs after fixes) + holdout on unseen data
A2: Model gpt-4o-mini · test dates 2026-10-04 to 2026-10-08 · every number below is a live formula over the bundle sheets. After-fix numbers are Hinglish; Hindi and English after-fix runs are planned once all bundles are fixed.
A3: z (95%) | B3: 1.96 | C3: Wilson interval z-value (input).
A4: Final result on unseen data (Holdout round 2, 135 statements): | E4: ='Holdout Summary'!G16 -> 0.75301205 | F4: strict accuracy | G4: ='Holdout Summary'!K16 -> 0.096385542 | H4: silent-error rate (see 'Holdout Summary')
A5: 1. Before vs after — all categories
A6: Bundle / run | B6: Rows | C6: Strict accuracy | D6: 95% CI low | E6: 95% CI high | F6: Safe rate | G6: Silent-error rate
A7: Employee — before (v1), Hinglish | B7: =B40 -> 64 | C7: =G40 -> 0.421875 | D7: =H40 -> 0.30869594 | E7: =I40 -> 0.54390188 | F7: =J40 -> 0.46875 | G7: =K40 -> 0.234375
A8: Employee — after fixes (full run 5 Oct 13:49), Hinglish | B8: =B50 -> 66 | C8: =G50 -> 0.89393939 | D8: =H50 -> 0.79687474 | E8: =I50 -> 0.94766719 | F8: =J50 -> 0.90909091 | G8: =K50 -> 0.075757576
A9: Customer — before (v1), Hinglish | B9: =B60 -> 72 | C9: =G60 -> 0.54166667 | D9: =H60 -> 0.42739664 | E9: =I60 -> 0.65171561 | F9: =J60 -> 0.54166667 | G9: =K60 -> 0.16666667
A10: Customer — after fixes (full run 5 Oct 22:14), Hinglish | B10: =B70 -> 67 | C10: =G70 -> 0.95522388 | D10: =H70 -> 0.87641967 | E10: =I70 -> 0.9846563 | F10: =J70 -> 0.98507463 | G10: =K70 -> 0.014925373
A11: Supplier — before (baseline), Hinglish | B11: =B80 -> 86 | C11: =G80 -> 0.51162791 | D11: =H80 -> 0.40776537 | E11: =I80 -> 0.61449603 | F11: =J80 -> 0.58139535 | G11: =K80 -> 0.15116279
A12: Supplier — after fixes (full run 6 Oct 15:27), Hinglish | B12: =B90 -> 82 | C12: =G90 -> 0.85365854 | D12: =H90 -> 0.76140386 | E12: =I90 -> 0.91425922 | F12: =J90 -> 0.8902439 | G12: =K90 -> 0.085365854
A13: Expense — before (baseline), Hinglish | B13: =B100 -> 109 | C13: =G100 -> 0.47706422 | D13: =H100 -> 0.38568353 | E13: =I100 -> 0.57000657 | F13: =J100 -> 0.55963303 | G13: =K100 -> 0.10091743
A14: Expense — after fixes (full run 6 Oct 17:42), Hinglish | B14: =B110 -> 105 | C14: =G110 -> 0.96190476 | D14: =H110 -> 0.90611558 | E14: =I110 -> 0.98508778 | F14: =J110 -> 0.99047619 | G14: =K110 -> 0
A15: Family — before (baseline), Hinglish | B15: =B120 -> 75 | C15: =G120 -> 0.54666667 | D15: =H120 -> 0.43448174 | E15: =I120 -> 0.65430388 | F15: =J120 -> 0.65333333 | G15: =K120 -> 0.16
A16: Family — after fixes (full run 7 Oct 12:15), Hinglish | B16: =B130 -> 69 | C16: =G130 -> 0.97101449 | D16: =H130 -> 0.90033227 | E16: =I130 -> 0.99201496 | F16: =J130 -> 0.98550725 | G16: =K130 -> 0.014492754
A17: Stock — before (baseline), Hinglish | B17: =B140 -> 67 | C17: =G140 -> 0.62686567 | D17: =H140 -> 0.50715186 | E17: =I140 -> 0.73282013 | F17: =J140 -> 0.64179104 | G17: =K140 -> 0.059701493
A18: Stock — after fixes (full run 8 Oct 07:07), Hinglish | B18: =B150 -> 64 | C18: =G150 -> 0.96875 | D18: =H150 -> 0.89302506 | E18: =I150 -> 0.99138804 | F18: =J150 -> 0.96875 | G18: =K150 -> 0
A19: Purchase — before (baseline), Hinglish | B19: =B160 -> 74 | C19: =G160 -> 0.75675676 | D19: =H160 -> 0.64793456 | E19: =I160 -> 0.84023629 | F19: =J160 -> 0.75675676 | G19: =K160 -> 0.10810811
A20: Purchase — after fixes (full run 8 Oct 13:17), Hinglish | B20: =B170 -> 72 | C20: =G170 -> 0.88888889 | D20: =H170 -> 0.79576856 | E20: =I170 -> 0.94261249 | F20: =J170 -> 0.88888889 | G20: =K170 -> 0.027777778
A21: Report — before (baseline), Hinglish | B21: =B179 -> 20 | C21: =G179 -> 0.7 | D21: =H179 -> 0.48102322 | E21: =I179 -> 0.85452473 | F21: =J179 -> 0.7 | G21: =K179 -> 0.25
A22: Report — after fixes (full run 8 Oct 11:16), Hinglish | B22: =B189 -> 20 | C22: =G189 -> 1 | D22: =H189 -> 0.83886987 | E22: =I189 -> 1 | F22: =J189 -> 1 | G22: =K189 -> 0
A23: Correction — before (baseline), Hinglish | B23: =B199 -> 25 | C23: =G199 -> 0.76 | D23: =H199 -> 0.5656994 | E23: =I199 -> 0.88503842 | F23: =J199 -> 0.76 | G23: =K199 -> 0.24
A24: Correction — after fixes (latest per test: 11:28 full + 11:57 re-run), Hinglish | B24: =B209 -> 25 | C24: =G209 -> 0.96 | D24: =H209 -> 0.80455528 | E24: =I209 -> 0.99290395 | F24: =J209 -> 0.96 | G24: =K209 -> 0.04
A25: Router — single full run (12:27), Hinglish | B25: =B219 -> 30 | C25: =G219 -> 1 | D25: =H219 -> 0.88648291 | E25: =I219 -> 1 | F25: =J219 -> 1 | G25: =K219 -> 0
A26: Employee — before (v1), Hindi | B26: =B230 -> 64 | C26: =G230 -> 0.4375 | D26: =H230 -> 0.32293817 | E26: =I230 -> 0.55914008 | F26: =J230 -> 0.53125 | G26: =K230 -> 0.140625
A27: Employee — before (v1), English | B27: =B240 -> 66 | C27: =G240 -> 0.48484848 | D27: =H240 -> 0.36846762 | E27: =I240 -> 0.60289615 | F27: =J240 -> 0.53030303 | G27: =K240 -> 0.16666667
A28: Employee F — fields correct (latest per test, not a full run) | B28: =COUNTA('Employee F'!$G$5:$G$63) -> 59 | C28: =IF(B28=0,"",COUNTIF('Employee F'!$G$5:$G$63,"Y")/B28) -> 0.86440678
A29: After = the last FULL run of each bundle (every test in one run; run file named in the row). Exceptions, marked in the row: Correction and Employee F (latest result per test).
A30: Supplier fixes changed shared steps (extraction, grouping, dates, amounts). Customer and Employee were re-checked on ~40 selected tests (all passed), not re-run in full — see Known issues.
A33: 2. Employee — before (v1), Hinglish
A34: Category | B34: Rows | C34: Correct | D34: Safe ask | E34: Silent wrong | F34: Missed | G34: Strict accuracy | H34: 95% CI low | I34: 95% CI high | J34: Safe rate | K34: Silent-error rate
A35: A - Daily | B35: =COUNTIFS(Employee!$M$5:$M$72,"<>",Employee!$B$5:$B$72,"A - Daily") -> 10 | C35: =COUNTIFS(Employee!$M$5:$M$72,"Correct",Employee!$B$5:$B$72,"A - Daily") -> 4 | D35: =COUNTIFS(Employee!$M$5:$M$72,"Safe ask",Employee!$B$5:$B$72,"A - Daily") -> 0 | E35: =COUNTIFS(Employee!$M$5:$M$72,"Silent wrong",Employee!$B$5:$B$72,"A - Daily") -> 1 | F35: =COUNTIFS(Employee!$M$5:$M$72,"Missed",Employee!$B$5:$B$72,"A - Daily") -> 5 | G35: =IF(B35=0,"",C35/B35) -> 0.4 | H35: =IF(B35=0,"",(((C35/B35)+$B$3^2/(2*B35))-($B$3*SQRT((C35/B35)*(1-(C35/B35))/B35+$B$3^2/(4*B35^2))))/(1+$B$3^2/B35)) -> 0.16817758 | I35: =IF(B35=0,"",(((C35/B35)+$B$3^2/(2*B35))+($B$3*SQRT((C35/B35)*(1-(C35/B35))/B35+$B$3^2/(4*B35^2))))/(1+$B$3^2/B35)) -> 0.68733045 | J35: =IF(B35=0,"",(C35+D35)/B35) -> 0.4 | K35: =IF(B35=0,"",E35/B35) -> 0.1
A36: B - Tricky | B36: =COUNTIFS(Employee!$M$5:$M$72,"<>",Employee!$B$5:$B$72,"B - Tricky") -> 10 | C36: =COUNTIFS(Employee!$M$5:$M$72,"Correct",Employee!$B$5:$B$72,"B - Tricky") -> 5 | D36: =COUNTIFS(Employee!$M$5:$M$72,"Safe ask",Employee!$B$5:$B$72,"B - Tricky") -> 0 | E36: =COUNTIFS(Employee!$M$5:$M$72,"Silent wrong",Employee!$B$5:$B$72,"B - Tricky") -> 4 | F36: =COUNTIFS(Employee!$M$5:$M$72,"Missed",Employee!$B$5:$B$72,"B - Tricky") -> 1 | G36: =IF(B36=0,"",C36/B36) -> 0.5 | H36: =IF(B36=0,"",(((C36/B36)+$B$3^2/(2*B36))-($B$3*SQRT((C36/B36)*(1-(C36/B36))/B36+$B$3^2/(4*B36^2))))/(1+$B$3^2/B36)) -> 0.23658959 | I36: =IF(B36=0,"",(((C36/B36)+$B$3^2/(2*B36))+($B$3*SQRT((C36/B36)*(1-(C36/B36))/B36+$B$3^2/(4*B36^2))))/(1+$B$3^2/B36)) -> 0.76341041 | J36: =IF(B36=0,"",(C36+D36)/B36) -> 0.5 | K36: =IF(B36=0,"",E36/B36) -> 0.4
A37: C - Edge | B37: =COUNTIFS(Employee!$M$5:$M$72,"<>",Employee!$B$5:$B$72,"C - Edge") -> 10 | C37: =COUNTIFS(Employee!$M$5:$M$72,"Correct",Employee!$B$5:$B$72,"C - Edge") -> 3 | D37: =COUNTIFS(Employee!$M$5:$M$72,"Safe ask",Employee!$B$5:$B$72,"C - Edge") -> 2 | E37: =COUNTIFS(Employee!$M$5:$M$72,"Silent wrong",Employee!$B$5:$B$72,"C - Edge") -> 3 | F37: =COUNTIFS(Employee!$M$5:$M$72,"Missed",Employee!$B$5:$B$72,"C - Edge") -> 2 | G37: =IF(B37=0,"",C37/B37) -> 0.3 | H37: =IF(B37=0,"",(((C37/B37)+$B$3^2/(2*B37))-($B$3*SQRT((C37/B37)*(1-(C37/B37))/B37+$B$3^2/(4*B37^2))))/(1+$B$3^2/B37)) -> 0.10778929 | I37: =IF(B37=0,"",(((C37/B37)+$B$3^2/(2*B37))+($B$3*SQRT((C37/B37)*(1-(C37/B37))/B37+$B$3^2/(4*B37^2))))/(1+$B$3^2/B37)) -> 0.60322678 | J37: =IF(B37=0,"",(C37+D37)/B37) -> 0.5 | K37: =IF(B37=0,"",E37/B37) -> 0.3
A38: D - Other business | B38: =COUNTIFS(Employee!$M$5:$M$72,"<>",Employee!$B$5:$B$72,"D - Other business") -> 10 | C38: =COUNTIFS(Employee!$M$5:$M$72,"Correct",Employee!$B$5:$B$72,"D - Other business") -> 3 | D38: =COUNTIFS(Employee!$M$5:$M$72,"Safe ask",Employee!$B$5:$B$72,"D - Other business") -> 1 | E38: =COUNTIFS(Employee!$M$5:$M$72,"Silent wrong",Employee!$B$5:$B$72,"D - Other business") -> 5 | F38: =COUNTIFS(Employee!$M$5:$M$72,"Missed",Employee!$B$5:$B$72,"D - Other business") -> 1 | G38: =IF(B38=0,"",C38/B38) -> 0.3 | H38: =IF(B38=0,"",(((C38/B38)+$B$3^2/(2*B38))-($B$3*SQRT((C38/B38)*(1-(C38/B38))/B38+$B$3^2/(4*B38^2))))/(1+$B$3^2/B38)) -> 0.10778929 | I38: =IF(B38=0,"",(((C38/B38)+$B$3^2/(2*B38))+($B$3*SQRT((C38/B38)*(1-(C38/B38))/B38+$B$3^2/(4*B38^2))))/(1+$B$3^2/B38)) -> 0.60322678 | J38: =IF(B38=0,"",(C38+D38)/B38) -> 0.4 | K38: =IF(B38=0,"",E38/B38) -> 0.5
A39: E - Mixed | B39: =COUNTIFS(Employee!$M$5:$M$72,"<>",Employee!$B$5:$B$72,"E - Mixed") -> 24 | C39: =COUNTIFS(Employee!$M$5:$M$72,"Correct",Employee!$B$5:$B$72,"E - Mixed") -> 12 | D39: =COUNTIFS(Employee!$M$5:$M$72,"Safe ask",Employee!$B$5:$B$72,"E - Mixed") -> 0 | E39: =COUNTIFS(Employee!$M$5:$M$72,"Silent wrong",Employee!$B$5:$B$72,"E - Mixed") -> 2 | F39: =COUNTIFS(Employee!$M$5:$M$72,"Missed",Employee!$B$5:$B$72,"E - Mixed") -> 10 | G39: =IF(B39=0,"",C39/B39) -> 0.5 | H39: =IF(B39=0,"",(((C39/B39)+$B$3^2/(2*B39))-($B$3*SQRT((C39/B39)*(1-(C39/B39))/B39+$B$3^2/(4*B39^2))))/(1+$B$3^2/B39)) -> 0.31427132 | I39: =IF(B39=0,"",(((C39/B39)+$B$3^2/(2*B39))+($B$3*SQRT((C39/B39)*(1-(C39/B39))/B39+$B$3^2/(4*B39^2))))/(1+$B$3^2/B39)) -> 0.68572868 | J39: =IF(B39=0,"",(C39+D39)/B39) -> 0.5 | K39: =IF(B39=0,"",E39/B39) -> 0.083333333
A40: All categories | B40: =COUNTIFS(Employee!$M$5:$M$72,"<>") -> 64 | C40: =COUNTIFS(Employee!$M$5:$M$72,"Correct") -> 27 | D40: =COUNTIFS(Employee!$M$5:$M$72,"Safe ask") -> 3 | E40: =COUNTIFS(Employee!$M$5:$M$72,"Silent wrong") -> 15 | F40: =COUNTIFS(Employee!$M$5:$M$72,"Missed") -> 19 | G40: =IF(B40=0,"",C40/B40) -> 0.421875 | H40: =IF(B40=0,"",(((C40/B40)+$B$3^2/(2*B40))-($B$3*SQRT((C40/B40)*(1-(C40/B40))/B40+$B$3^2/(4*B40^2))))/(1+$B$3^2/B40)) -> 0.30869594 | I40: =IF(B40=0,"",(((C40/B40)+$B$3^2/(2*B40))+($B$3*SQRT((C40/B40)*(1-(C40/B40))/B40+$B$3^2/(4*B40^2))))/(1+$B$3^2/B40)) -> 0.54390188 | J40: =IF(B40=0,"",(C40+D40)/B40) -> 0.46875 | K40: =IF(B40=0,"",E40/B40) -> 0.234375
A43: 3. Employee — after fixes (full run 5 Oct 13:49), Hinglish
A44: Category | B44: Rows | C44: Correct | D44: Safe ask | E44: Silent wrong | F44: Missed | G44: Strict accuracy | H44: 95% CI low | I44: 95% CI high | J44: Safe rate | K44: Silent-error rate
...

Sheet Holdout Summary
A1: Final evaluation on unseen data (holdout) — round 1 vs round 2 (final)
A2: Numbers are live formulas over the two holdout sheets (Wilson 95% interval, z from Summary!B3). 'Tests fully right' = every expected entry of the statement correct (counted from the run files).
A4: 1. Holdout round 2 — FINAL (run 2026-10-08 16:51, no fixes after it)
A5: Bundle | B5: Rows | C5: Correct | D5: Safe ask | E5: Silent wrong | F5: Missed | G5: Strict accuracy | H5: 95% CI low | I5: 95% CI high | J5: Safe rate | K5: Silent-error rate | L5: Tests fully right
A6: Employee | B6: =COUNTIFS('Holdout R2 (final)'!$I$5:$I$170,"<>",'Holdout R2 (final)'!$B$5:$B$170,"Employee") -> 18 | C6: =COUNTIFS('Holdout R2 (final)'!$I$5:$I$170,"Correct",'Holdout R2 (final)'!$B$5:$B$170,"Employee") -> 16 | D6: =COUNTIFS('Holdout R2 (final)'!$I$5:$I$170,"Safe ask",'Holdout R2 (final)'!$B$5:$B$170,"Employee") -> 0 | E6: =COUNTIFS('Holdout R2 (final)'!$I$5:$I$170,"Silent wrong",'Holdout R2 (final)'!$B$5:$B$170,"Employee") -> 0 | F6: =COUNTIFS('Holdout R2 (final)'!$I$5:$I$170,"Missed",'Holdout R2 (final)'!$B$5:$B$170,"Employee") -> 2 | G6: =IF(B6=0,"",C6/B6) -> 0.88888889 | H6: =IF(B6=0,"",(((C6/B6)+Summary!$B$3^2/(2*B6))-(Summary!$B$3*SQRT((C6/B6)*(1-(C6/B6))/B6+Summary!$B$3^2/(4*B6^2))))/(1+Summary!$B$3^2/B6)) -> 0.67199755 | I6: =IF(B6=0,"",(((C6/B6)+Summary!$B$3^2/(2*B6))+(Summary!$B$3*SQRT((C6/B6)*(1-(C6/B6))/B6+Summary!$B$3^2/(4*B6^2))))/(1+Summary!$B$3^2/B6)) -> 0.96898113 | J6: =IF(B6=0,"",(C6+D6)/B6) -> 0.88888889 | K6: =IF(B6=0,"",E6/B6) -> 0 | L6: 13/15
A7: Customer | B7: =COUNTIFS('Holdout R2 (final)'!$I$5:$I$170,"<>",'Holdout R2 (final)'!$B$5:$B$170,"Customer") -> 18 | C7: =COUNTIFS('Holdout R2 (final)'!$I$5:$I$170,"Correct",'Holdout R2 (final)'!$B$5:$B$170,"Customer") -> 11 | D7: =COUNTIFS('Holdout R2 (final)'!$I$5:$I$170,"Safe ask",'Holdout R2 (final)'!$B$5:$B$170,"Customer") -> 1 | E7: =COUNTIFS('Holdout R2 (final)'!$I$5:$I$170,"Silent wrong",'Holdout R2 (final)'!$B$5:$B$170,"Customer") -> 2 | F7: =COUNTIFS('Holdout R2 (final)'!$I$5:$I$170,"Missed",'Holdout R2 (final)'!$B$5:$B$170,"Customer") -> 4 | G7: =IF(B7=0,"",C7/B7) -> 0.61111111 | H7: =IF(B7=0,"",(((C7/B7)+Summary!$B$3^2/(2*B7))-(Summary!$B$3*SQRT((C7/B7)*(1-(C7/B7))/B7+Summary!$B$3^2/(4*B7^2))))/(1+Summary!$B$3^2/B7)) -> 0.38618669 | I7: =IF(B7=0,"",(((C7/B7)+Summary!$B$3^2/(2*B7))+(Summary!$B$3*SQRT((C7/B7)*(1-(C7/B7))/B7+Summary!$B$3^2/(4*B7^2))))/(1+Summary!$B$3^2/B7)) -> 0.79695008 | J7: =IF(B7=0,"",(C7+D7)/B7) -> 0.66666667 | K7: =IF(B7=0,"",E7/B7) -> 0.11111111 | L7: 8/15
A8: Supplier | B8: =COUNTIFS('Holdout R2 (final)'!$I$5:$I$170,"<>",'Holdout R2 (final)'!$B$5:$B$170,"Supplier") -> 16 | C8: =COUNTIFS('Holdout R2 (final)'!$I$5:$I$170,"Correct",'Holdout R2 (final)'!$B$5:$B$170,"Supplier") -> 15 | D8: =COUNTIFS('Holdout R2 (final)'!$I$5:$I$170,"Safe ask",'Holdout R2 (final)'!$B$5:$B$170,"Supplier") -> 0 | E8: =COUNTIFS('Holdout R2 (final)'!$I$5:$I$170,"Silent wrong",'Holdout R2 (final)'!$B$5:$B$170,"Supplier") -> 1 | F8: =COUNTIFS('Holdout R2 (final)'!$I$5:$I$170,"Missed",'Holdout R2 (final)'!$B$5:$B$170,"Supplier") -> 0 | G8: =IF(B8=0,"",C8/B8) -> 0.9375 | H8: =IF(B8=0,"",(((C8/B8)+Summary!$B$3^2/(2*B8))-(Summary!$B$3*SQRT((C8/B8)*(1-(C8/B8))/B8+Summary!$B$3^2/(4*B8^2))))/(1+Summary!$B$3^2/B8)) -> 0.71670732 | I8: =IF(B8=0,"",(((C8/B8)+Summary!$B$3^2/(2*B8))+(Summary!$B$3*SQRT((C8/B8)*(1-(C8/B8))/B8+Summary!$B$3^2/(4*B8^2))))/(1+Summary!$B$3^2/B8)) -> 0.98888094 | J8: =IF(B8=0,"",(C8+D8)/B8) -> 0.9375 | K8: =IF(B8=0,"",E8/B8) -> 0.0625 | L8: 14/15
A9: Expense | B9: =COUNTIFS('Holdout R2 (final)'!$I$5:$I$170,"<>",'Holdout R2 (final)'!$B$5:$B$170,"Expense") -> 31 | C9: =COUNTIFS('Holdout R2 (final)'!$I$5:$I$170,"Correct",'Holdout R2 (final)'!$B$5:$B$170,"Expense") -> 24 | D9: =COUNTIFS('Holdout R2 (final)'!$I$5:$I$170,"Safe ask",'Holdout R2 (final)'!$B$5:$B$170,"Expense") -> 2 | E9: =COUNTIFS('Holdout R2 (final)'!$I$5:$I$170,"Silent wrong",'Holdout R2 (final)'!$B$5:$B$170,"Expense") -> 1 | F9: =COUNTIFS('Holdout R2 (final)'!$I$5:$I$170,"Missed",'Holdout R2 (final)'!$B$5:$B$170,"Expense") -> 4 | G9: =IF(B9=0,"",C9/B9) -> 0.77419355 | H9: =IF(B9=0,"",(((C9/B9)+Summary!$B$3^2/(2*B9))-(Summary!$B$3*SQRT((C9/B9)*(1-(C9/B9))/B9+Summary!$B$3^2/(4*B9^2))))/(1+Summary!$B$3^2/B9)) -> 0.6018724 | I9: =IF(B9=0,"",(((C9/B9)+Summary!$B$3^2/(2*B9))+(Summary!$B$3*SQRT((C9/B9)*(1-(C9/B9))/B9+Summary!$B$3^2/(4*B9^2))))/(1+Summary!$B$3^2/B9)) -> 0.88605008 | J9: =IF(B9=0,"",(C9+D9)/B9) -> 0.83870968 | K9: =IF(B9=0,"",E9/B9) -> 0.032258065 | L9: 12/15
A10: Family | B10: =COUNTIFS('Holdout R2 (final)'!$I$5:$I$170,"<>",'Holdout R2 (final)'!$B$5:$B$170,"Family") -> 17 | C10: =COUNTIFS('Holdout R2 (final)'!$I$5:$I$170,"Correct",'Holdout R2 (final)'!$B$5:$B$170,"Family") -> 11 | D10: =COUNTIFS('Holdout R2 (final)'!$I$5:$I$170,"Safe ask",'Holdout R2 (final)'!$B$5:$B$170,"Family") -> 1 | E10: =COUNTIFS('Holdout R2 (final)'!$I$5:$I$170,"Silent wrong",'Holdout R2 (final)'!$B$5:$B$170,"Family") -> 2 | F10: =COUNTIFS('Holdout R2 (final)'!$I$5:$I$170,"Missed",'Holdout R2 (final)'!$B$5:$B$170,"Family") -> 3 | G10: =IF(B10=0,"",C10/B10) -> 0.64705882 | H10: =IF(B10=0,"",(((C10/B10)+Summary!$B$3^2/(2*B10))-(Summary!$B$3*SQRT((C10/B10)*(1-(C10/B10))/B10+Summary!$B$3^2/(4*B10^2))))/(1+Summary!$B$3^2/B10)) -> 0.41299967 | I10: =IF(B10=0,"",(((C10/B10)+Summary!$B$3^2/(2*B10))+(Summary!$B$3*SQRT((C10/B10)*(1-(C10/B10))/B10+Summary!$B$3^2/(4*B10^2))))/(1+Summary!$B$3^2/B10)) -> 0.82690514 | J10: =IF(B10=0,"",(C10+D10)/B10) -> 0.70588235 | K10: =IF(B10=0,"",E10/B10) -> 0.11764706 | L10: 10/15
A11: Stock | B11: =COUNTIFS('Holdout R2 (final)'!$I$5:$I$170,"<>",'Holdout R2 (final)'!$B$5:$B$170,"Stock") -> 17 | C11: =COUNTIFS('Holdout R2 (final)'!$I$5:$I$170,"Correct",'Holdout R2 (final)'!$B$5:$B$170,"Stock") -> 13 | D11: =COUNTIFS('Holdout R2 (final)'!$I$5:$I$170,"Safe ask",'Holdout R2 (final)'!$B$5:$B$170,"Stock") -> 0 | E11: =COUNTIFS('Holdout R2 (final)'!$I$5:$I$170,"Silent wrong",'Holdout R2 (final)'!$B$5:$B$170,"Stock") -> 1 | F11: =COUNTIFS('Holdout R2 (final)'!$I$5:$I$170,"Missed",'Holdout R2 (final)'!$B$5:$B$170,"Stock") -> 3 | G11: =IF(B11=0,"",C11/B11) -> 0.76470588 | H11: =IF(B11=0,"",(((C11/B11)+Summary!$B$3^2/(2*B11))-(Summary!$B$3*SQRT((C11/B11)*(1-(C11/B11))/B11+Summary!$B$3^2/(4*B11^2))))/(1+Summary!$B$3^2/B11)) -> 0.52737754 | I11: =IF(B11=0,"",(((C11/B11)+Summary!$B$3^2/(2*B11))+(Summary!$B$3*SQRT((C11/B11)*(1-(C11/B11))/B11+Summary!$B$3^2/(4*B11^2))))/(1+Summary!$B$3^2/B11)) -> 0.90445111 | J11: =IF(B11=0,"",(C11+D11)/B11) -> 0.76470588 | K11: =IF(B11=0,"",E11/B11) -> 0.058823529 | L11: 12/15
A12: Purchase | B12: =COUNTIFS('Holdout R2 (final)'!$I$5:$I$170,"<>",'Holdout R2 (final)'!$B$5:$B$170,"Purchase") -> 19 | C12: =COUNTIFS('Holdout R2 (final)'!$I$5:$I$170,"Correct",'Holdout R2 (final)'!$B$5:$B$170,"Purchase") -> 11 | D12: =COUNTIFS('Holdout R2 (final)'!$I$5:$I$170,"Safe ask",'Holdout R2 (final)'!$B$5:$B$170,"Purchase") -> 2 | E12: =COUNTIFS('Holdout R2 (final)'!$I$5:$I$170,"Silent wrong",'Holdout R2 (final)'!$B$5:$B$170,"Purchase") -> 3 | F12: =COUNTIFS('Holdout R2 (final)'!$I$5:$I$170,"Missed",'Holdout R2 (final)'!$B$5:$B$170,"Purchase") -> 3 | G12: =IF(B12=0,"",C12/B12) -> 0.57894737 | H12: =IF(B12=0,"",(((C12/B12)+Summary!$B$3^2/(2*B12))-(Summary!$B$3*SQRT((C12/B12)*(1-(C12/B12))/B12+Summary!$B$3^2/(4*B12^2))))/(1+Summary!$B$3^2/B12)) -> 0.36275551 | I12: =IF(B12=0,"",(((C12/B12)+Summary!$B$3^2/(2*B12))+(Summary!$B$3*SQRT((C12/B12)*(1-(C12/B12))/B12+Summary!$B$3^2/(4*B12^2))))/(1+Summary!$B$3^2/B12)) -> 0.7685838 | J12: =IF(B12=0,"",(C12+D12)/B12) -> 0.68421053 | K12: =IF(B12=0,"",E12/B12) -> 0.15789474 | L12: 10/15
A13: Report | B13: =COUNTIFS('Holdout R2 (final)'!$I$5:$I$170,"<>",'Holdout R2 (final)'!$B$5:$B$170,"Report") -> 10 | C13: =COUNTIFS('Holdout R2 (final)'!$I$5:$I$170,"Correct",'Holdout R2 (final)'!$B$5:$B$170,"Report") -> 7 | D13: =COUNTIFS('Holdout R2 (final)'!$I$5:$I$170,"Safe ask",'Holdout R2 (final)'!$B$5:$B$170,"Report") -> 0 | E13: =COUNTIFS('Holdout R2 (final)'!$I$5:$I$170,"Silent wrong",'Holdout R2 (final)'!$B$5:$B$170,"Report") -> 3 | F13: =COUNTIFS('Holdout R2 (final)'!$I$5:$I$170,"Missed",'Holdout R2 (final)'!$B$5:$B$170,"Report") -> 0 | G13: =IF(B13=0,"",C13/B13) -> 0.7 | H13: =IF(B13=0,"",(((C13/B13)+Summary!$B$3^2/(2*B13))-(Summary!$B$3*SQRT((C13/B13)*(1-(C13/B13))/B13+Summary!$B$3^2/(4*B13^2))))/(1+Summary!$B$3^2/B13)) -> 0.39677322 | I13: =IF(B13=0,"",(((C13/B13)+Summary!$B$3^2/(2*B13))+(Summary!$B$3*SQRT((C13/B13)*(1-(C13/B13))/B13+Summary!$B$3^2/(4*B13^2))))/(1+Summary!$B$3^2/B13)) -> 0.89221071 | J13: =IF(B13=0,"",(C13+D13)/B13) -> 0.7 | K13: =IF(B13=0,"",E13/B13) -> 0.3 | L13: 7/10
A14: Correction | B14: =COUNTIFS('Holdout R2 (final)'!$I$5:$I$170,"<>",'Holdout R2 (final)'!$B$5:$B$170,"Correction") -> 10 | C14: =COUNTIFS('Holdout R2 (final)'!$I$5:$I$170,"Correct",'Holdout R2 (final)'!$B$5:$B$170,"Correction") -> 8 | D14: =COUNTIFS('Holdout R2 (final)'!$I$5:$I$170,"Safe ask",'Holdout R2 (final)'!$B$5:$B$170,"Correction") -> 0 | E14: =COUNTIFS('Holdout R2 (final)'!$I$5:$I$170,"Silent wrong",'Holdout R2 (final)'!$B$5:$B$170,"Correction") -> 2 | F14: =COUNTIFS('Holdout R2 (final)'!$I$5:$I$170,"Missed",'Holdout R2 (final)'!$B$5:$B$170,"Correction") -> 0 | G14: =IF(B14=0,"",C14/B14) -> 0.8 | H14: =IF(B14=0,"",(((C14/B14)+Summary!$B$3^2/(2*B14))-(Summary!$B$3*SQRT((C14/B14)*(1-(C14/B14))/B14+Summary!$B$3^2/(4*B14^2))))/(1+Summary!$B$3^2/B14)) -> 0.49015685 | I14: =IF(B14=0,"",(((C14/B14)+Summary!$B$3^2/(2*B14))+(Summary!$B$3*SQRT((C14/B14)*(1-(C14/B14))/B14+Summary!$B$3^2/(4*B14^2))))/(1+Summary!$B$3^2/B14)) -> 0.94331905 | J14: =IF(B14=0,"",(C14+D14)/B14) -> 0.8 | K14: =IF(B14=0,"",E14/B14) -> 0.2 | L14: 8/10
A15: Router | B15: =COUNTIFS('Holdout R2 (final)'!$I$5:$I$170,"<>",'Holdout R2 (final)'!$B$5:$B$170,"Router") -> 10 | C15: =COUNTIFS('Holdout R2 (final)'!$I$5:$I$170,"Correct",'Holdout R2 (final)'!$B$5:$B$170,"Router") -> 9 | D15: =COUNTIFS('Holdout R2 (final)'!$I$5:$I$170,"Safe ask",'Holdout R2 (final)'!$B$5:$B$170,"Router") -> 0 | E15: =COUNTIFS('Holdout R2 (final)'!$I$5:$I$170,"Silent wrong",'Holdout R2 (final)'!$B$5:$B$170,"Router") -> 1 | F15: =COUNTIFS('Holdout R2 (final)'!$I$5:$I$170,"Missed",'Holdout R2 (final)'!$B$5:$B$170,"Router") -> 0 | G15: =IF(B15=0,"",C15/B15) -> 0.9 | H15: =IF(B15=0,"",(((C15/B15)+Summary!$B$3^2/(2*B15))-(Summary!$B$3*SQRT((C15/B15)*(1-(C15/B15))/B15+Summary!$B$3^2/(4*B15^2))))/(1+Summary!$B$3^2/B15)) -> 0.59584361 | I15: =IF(B15=0,"",(((C15/B15)+Summary!$B$3^2/(2*B15))+(Summary!$B$3*SQRT((C15/B15)*(1-(C15/B15))/B15+Summary!$B$3^2/(4*B15^2))))/(1+Summary!$B$3^2/B15)) -> 0.98212425 | J15: =IF(B15=0,"",(C15+D15)/B15) -> 0.9 | K15: =IF(B15=0,"",E15/B15) -> 0.1 | L15: 9/10
A16: All | B16: =COUNTIFS('Holdout R2 (final)'!$I$5:$I$170,"<>") -> 166 | C16: =COUNTIFS('Holdout R2 (final)'!$I$5:$I$170,"Correct") -> 125 | D16: =COUNTIFS('Holdout R2 (final)'!$I$5:$I$170,"Safe ask") -> 6 | E16: =COUNTIFS('Holdout R2 (final)'!$I$5:$I$170,"Silent wrong") -> 16 | F16: =COUNTIFS('Holdout R2 (final)'!$I$5:$I$170,"Missed") -> 19 | G16: =IF(B16=0,"",C16/B16) -> 0.75301205 | H16: =IF(B16=0,"",(((C16/B16)+Summary!$B$3^2/(2*B16))-(Summary!$B$3*SQRT((C16/B16)*(1-(C16/B16))/B16+Summary!$B$3^2/(4*B16^2))))/(1+Summary!$B$3^2/B16)) -> 0.68217786 | I16: =IF(B16=0,"",(((C16/B16)+Summary!$B$3^2/(2*B16))+(Summary!$B$3*SQRT((C16/B16)*(1-(C16/B16))/B16+Summary!$B$3^2/(4*B16^2))))/(1+Summary!$B$3^2/B16)) -> 0.81240062 | J16: =IF(B16=0,"",(C16+D16)/B16) -> 0.78915663 | K16: =IF(B16=0,"",E16/B16) -> 0.096385542 | L16: 103/135
A19: 2. Holdout round 1 (run 2026-10-08 14:40; used for fixes afterwards)
A20: Bundle | B20: Rows | C20: Correct | D20: Safe ask | E20: Silent wrong | F20: Missed | G20: Strict accuracy | H20: 95% CI low | I20: 95% CI high | J20: Safe rate | K20: Silent-error rate | L20: Tests fully right
A21: Employee | B21: =COUNTIFS('Holdout R1'!$I$5:$I$182,"<>",'Holdout R1'!$B$5:$B$182,"Employee") -> 19 | C21: =COUNTIFS('Holdout R1'!$I$5:$I$182,"Correct",'Holdout R1'!$B$5:$B$182,"Employee") -> 15 | D21: =COUNTIFS('Holdout R1'!$I$5:$I$182,"Safe ask",'Holdout R1'!$B$5:$B$182,"Employee") -> 1 | E21: =COUNTIFS('Holdout R1'!$I$5:$I$182,"Silent wrong",'Holdout R1'!$B$5:$B$182,"Employee") -> 2 | F21: =COUNTIFS('Holdout R1'!$I$5:$I$182,"Missed",'Holdout R1'!$B$5:$B$182,"Employee") -> 1 | G21: =IF(B21=0,"",C21/B21) -> 0.78947368 | H21: =IF(B21=0,"",(((C21/B21)+Summary!$B$3^2/(2*B21))-(Summary!$B$3*SQRT((C21/B21)*(1-(C21/B21))/B21+Summary!$B$3^2/(4*B21^2))))/(1+Summary!$B$3^2/B21)) -> 0.56665286 | I21: =IF(B21=0,"",(((C21/B21)+Summary!$B$3^2/(2*B21))+(Summary!$B$3*SQRT((C21/B21)*(1-(C21/B21))/B21+Summary!$B$3^2/(4*B21^2))))/(1+Summary!$B$3^2/B21)) -> 0.91492462 | J21: =IF(B21=0,"",(C21+D21)/B21) -> 0.84210526 | K21: =IF(B21=0,"",E21/B21) -> 0.10526316 | L21: 12/15
A22: Customer | B22: =COUNTIFS('Holdout R1'!$I$5:$I$182,"<>",'Holdout R1'!$B$5:$B$182,"Customer") -> 19 | C22: =COUNTIFS('Holdout R1'!$I$5:$I$182,"Correct",'Holdout R1'!$B$5:$B$182,"Customer") -> 11 | D22: =COUNTIFS('Holdout R1'!$I$5:$I$182,"Safe ask",'Holdout R1'!$B$5:$B$182,"Customer") -> 0 | E22: =COUNTIFS('Holdout R1'!$I$5:$I$182,"Silent wrong",'Holdout R1'!$B$5:$B$182,"Customer") -> 6 | F22: =COUNTIFS('Holdout R1'!$I$5:$I$182,"Missed",'Holdout R1'!$B$5:$B$182,"Customer") -> 2 | G22: =IF(B22=0,"",C22/B22) -> 0.57894737 | H22: =IF(B22=0,"",(((C22/B22)+Summary!$B$3^2/(2*B22))-(Summary!$B$3*SQRT((C22/B22)*(1-(C22/B22))/B22+Summary!$B$3^2/(4*B22^2))))/(1+Summary!$B$3^2/B22)) -> 0.36275551 | I22: =IF(B22=0,"",(((C22/B22)+Summary!$B$3^2/(2*B22))+(Summary!$B$3*SQRT((C22/B22)*(1-(C22/B22))/B22+Summary!$B$3^2/(4*B22^2))))/(1+Summary!$B$3^2/B22)) -> 0.7685838 | J22: =IF(B22=0,"",(C22+D22)/B22) -> 0.57894737 | K22: =IF(B22=0,"",E22/B22) -> 0.31578947 | L22: 9/15
A23: Supplier | B23: =COUNTIFS('Holdout R1'!$I$5:$I$182,"<>",'Holdout R1'!$B$5:$B$182,"Supplier") -> 18 | C23: =COUNTIFS('Holdout R1'!$I$5:$I$182,"Correct",'Holdout R1'!$B$5:$B$182,"Supplier") -> 10 | D23: =COUNTIFS('Holdout R1'!$I$5:$I$182,"Safe ask",'Holdout R1'!$B$5:$B$182,"Supplier") -> 1 | E23: =COUNTIFS('Holdout R1'!$I$5:$I$182,"Silent wrong",'Holdout R1'!$B$5:$B$182,"Supplier") -> 3 | F23: =COUNTIFS('Holdout R1'!$I$5:$I$182,"Missed",'Holdout R1'!$B$5:$B$182,"Supplier") -> 4 | G23: =IF(B23=0,"",C23/B23) -> 0.55555556 | H23: =IF(B23=0,"",(((C23/B23)+Summary!$B$3^2/(2*B23))-(Summary!$B$3*SQRT((C23/B23)*(1-(C23/B23))/B23+Summary!$B$3^2/(4*B23^2))))/(1+Summary!$B$3^2/B23)) -> 0.33716069 | I23: =IF(B23=0,"",(((C23/B23)+Summary!$B$3^2/(2*B23))+(Summary!$B$3*SQRT((C23/B23)*(1-(C23/B23))/B23+Summary!$B$3^2/(4*B23^2))))/(1+Summary!$B$3^2/B23)) -> 0.75440769 | J23: =IF(B23=0,"",(C23+D23)/B23) -> 0.61111111 | K23: =IF(B23=0,"",E23/B23) -> 0.16666667 | L23: 9/15
A24: Expense | B24: =COUNTIFS('Holdout R1'!$I$5:$I$182,"<>",'Holdout R1'!$B$5:$B$182,"Expense") -> 33 | C24: =COUNTIFS('Holdout R1'!$I$5:$I$182,"Correct",'Holdout R1'!$B$5:$B$182,"Expense") -> 16 | D24: =COUNTIFS('Holdout R1'!$I$5:$I$182,"Safe ask",'Holdout R1'!$B$5:$B$182,"Expense") -> 0 | E24: =COUNTIFS('Holdout R1'!$I$5:$I$182,"Silent wrong",'Holdout R1'!$B$5:$B$182,"Expense") -> 7 | F24: =COUNTIFS('Holdout R1'!$I$5:$I$182,"Missed",'Holdout R1'!$B$5:$B$182,"Expense") -> 10 | G24: =IF(B24=0,"",C24/B24) -> 0.48484848 | H24: =IF(B24=0,"",(((C24/B24)+Summary!$B$3^2/(2*B24))-(Summary!$B$3*SQRT((C24/B24)*(1-(C24/B24))/B24+Summary!$B$3^2/(4*B24^2))))/(1+Summary!$B$3^2/B24)) -> 0.32503782 | I24: =IF(B24=0,"",(((C24/B24)+Summary!$B$3^2/(2*B24))+(Summary!$B$3*SQRT((C24/B24)*(1-(C24/B24))/B24+Summary!$B$3^2/(4*B24^2))))/(1+Summary!$B$3^2/B24)) -> 0.64781895 | J24: =IF(B24=0,"",(C24+D24)/B24) -> 0.48484848 | K24: =IF(B24=0,"",E24/B24) -> 0.21212121 | L24: 6/15
A25: Family | B25: =COUNTIFS('Holdout R1'!$I$5:$I$182,"<>",'Holdout R1'!$B$5:$B$182,"Family") -> 19 | C25: =COUNTIFS('Holdout R1'!$I$5:$I$182,"Correct",'Holdout R1'!$B$5:$B$182,"Family") -> 12 | D25: =COUNTIFS('Holdout R1'!$I$5:$I$182,"Safe ask",'Holdout R1'!$B$5:$B$182,"Family") -> 1 | E25: =COUNTIFS('Holdout R1'!$I$5:$I$182,"Silent wrong",'Holdout R1'!$B$5:$B$182,"Family") -> 4 | F25: =COUNTIFS('Holdout R1'!$I$5:$I$182,"Missed",'Holdout R1'!$B$5:$B$182,"Family") -> 2 | G25: =IF(B25=0,"",C25/B25) -> 0.63157895 | H25: =IF(B25=0,"",(((C25/B25)+Summary!$B$3^2/(2*B25))-(Summary!$B$3*SQRT((C25/B25)*(1-(C25/B25))/B25+Summary!$B$3^2/(4*B25^2))))/(1+Summary!$B$3^2/B25)) -> 0.41039157 | I25: =IF(B25=0,"",(((C25/B25)+Summary!$B$3^2/(2*B25))+(Summary!$B$3*SQRT((C25/B25)*(1-(C25/B25))/B25+Summary!$B$3^2/(4*B25^2))))/(1+Summary!$B$3^2/B25)) -> 0.80850728 | J25: =IF(B25=0,"",(C25+D25)/B25) -> 0.68421053 | K25: =IF(B25=0,"",E25/B25) -> 0.21052632 | L25: 10/15
A26: Stock | B26: =COUNTIFS('Holdout R1'!$I$5:$I$182,"<>",'Holdout R1'!$B$5:$B$182,"Stock") -> 18 | C26: =COUNTIFS('Holdout R1'!$I$5:$I$182,"Correct",'Holdout R1'!$B$5:$B$182,"Stock") -> 11 | D26: =COUNTIFS('Holdout R1'!$I$5:$I$182,"Safe ask",'Holdout R1'!$B$5:$B$182,"Stock") -> 0 | E26: =COUNTIFS('Holdout R1'!$I$5:$I$182,"Silent wrong",'Holdout R1'!$B$5:$B$182,"Stock") -> 2 | F26: =COUNTIFS('Holdout R1'!$I$5:$I$182,"Missed",'Holdout R1'!$B$5:$B$182,"Stock") -> 5 | G26: =IF(B26=0,"",C26/B26) -> 0.61111111 | H26: =IF(B26=0,"",(((C26/B26)+Summary!$B$3^2/(2*B26))-(Summary!$B$3*SQRT((C26/B26)*(1-(C26/B26))/B26+Summary!$B$3^2/(4*B26^2))))/(1+Summary!$B$3^2/B26)) -> 0.38618669 | I26: =IF(B26=0,"",(((C26/B26)+Summary!$B$3^2/(2*B26))+(Summary!$B$3*SQRT((C26/B26)*(1-(C26/B26))/B26+Summary!$B$3^2/(4*B26^2))))/(1+Summary!$B$3^2/B26)) -> 0.79695008 | J26: =IF(B26=0,"",(C26+D26)/B26) -> 0.61111111 | K26: =IF(B26=0,"",E26/B26) -> 0.11111111 | L26: 10/15
A27: Purchase | B27: =COUNTIFS('Holdout R1'!$I$5:$I$182,"<>",'Holdout R1'!$B$5:$B$182,"Purchase") -> 22 | C27: =COUNTIFS('Holdout R1'!$I$5:$I$182,"Correct",'Holdout R1'!$B$5:$B$182,"Purchase") -> 11 | D27: =COUNTIFS('Holdout R1'!$I$5:$I$182,"Safe ask",'Holdout R1'!$B$5:$B$182,"Purchase") -> 1 | E27: =COUNTIFS('Holdout R1'!$I$5:$I$182,"Silent wrong",'Holdout R1'!$B$5:$B$182,"Purchase") -> 5 | F27: =COUNTIFS('Holdout R1'!$I$5:$I$182,"Missed",'Holdout R1'!$B$5:$B$182,"Purchase") -> 5 | G27: =IF(B27=0,"",C27/B27) -> 0.5 | H27: =IF(B27=0,"",(((C27/B27)+Summary!$B$3^2/(2*B27))-(Summary!$B$3*SQRT((C27/B27)*(1-(C27/B27))/B27+Summary!$B$3^2/(4*B27^2))))/(1+Summary!$B$3^2/B27)) -> 0.30721805 | I27: =IF(B27=0,"",(((C27/B27)+Summary!$B$3^2/(2*B27))+(Summary!$B$3*SQRT((C27/B27)*(1-(C27/B27))/B27+Summary!$B$3^2/(4*B27^2))))/(1+Summary!$B$3^2/B27)) -> 0.69278195 | J27: =IF(B27=0,"",(C27+D27)/B27) -> 0.54545455 | K27: =IF(B27=0,"",E27/B27) -> 0.22727273 | L27: 8/15
A28: Report | B28: =COUNTIFS('Holdout R1'!$I$5:$I$182,"<>",'Holdout R1'!$B$5:$B$182,"Report") -> 10 | C28: =COUNTIFS('Holdout R1'!$I$5:$I$182,"Correct",'Holdout R1'!$B$5:$B$182,"Report") -> 7 | D28: =COUNTIFS('Holdout R1'!$I$5:$I$182,"Safe ask",'Holdout R1'!$B$5:$B$182,"Report") -> 0 | E28: =COUNTIFS('Holdout R1'!$I$5:$I$182,"Silent wrong",'Holdout R1'!$B$5:$B$182,"Report") -> 3 | F28: =COUNTIFS('Holdout R1'!$I$5:$I$182,"Missed",'Holdout R1'!$B$5:$B$182,"Report") -> 0 | G28: =IF(B28=0,"",C28/B28) -> 0.7 | H28: =IF(B28=0,"",(((C28/B28)+Summary!$B$3^2/(2*B28))-(Summary!$B$3*SQRT((C28/B28)*(1-(C28/B28))/B28+Summary!$B$3^2/(4*B28^2))))/(1+Summary!$B$3^2/B28)) -> 0.39677322 | I28: =IF(B28=0,"",(((C28/B28)+Summary!$B$3^2/(2*B28))+(Summary!$B$3*SQRT((C28/B28)*(1-(C28/B28))/B28+Summary!$B$3^2/(4*B28^2))))/(1+Summary!$B$3^2/B28)) -> 0.89221071 | J28: =IF(B28=0,"",(C28+D28)/B28) -> 0.7 | K28: =IF(B28=0,"",E28/B28) -> 0.3 | L28: 7/10
A29: Correction | B29: =COUNTIFS('Holdout R1'!$I$5:$I$182,"<>",'Holdout R1'!$B$5:$B$182,"Correction") -> 10 | C29: =COUNTIFS('Holdout R1'!$I$5:$I$182,"Correct",'Holdout R1'!$B$5:$B$182,"Correction") -> 9 | D29: =COUNTIFS('Holdout R1'!$I$5:$I$182,"Safe ask",'Holdout R1'!$B$5:$B$182,"Correction") -> 0 | E29: =COUNTIFS('Holdout R1'!$I$5:$I$182,"Silent wrong",'Holdout R1'!$B$5:$B$182,"Correction") -> 1 | F29: =COUNTIFS('Holdout R1'!$I$5:$I$182,"Missed",'Holdout R1'!$B$5:$B$182,"Correction") -> 0 | G29: =IF(B29=0,"",C29/B29) -> 0.9 | H29: =IF(B29=0,"",(((C29/B29)+Summary!$B$3^2/(2*B29))-(Summary!$B$3*SQRT((C29/B29)*(1-(C29/B29))/B29+Summary!$B$3^2/(4*B29^2))))/(1+Summary!$B$3^2/B29)) -> 0.59584361 | I29: =IF(B29=0,"",(((C29/B29)+Summary!$B$3^2/(2*B29))+(Summary!$B$3*SQRT((C29/B29)*(1-(C29/B29))/B29+Summary!$B$3^2/(4*B29^2))))/(1+Summary!$B$3^2/B29)) -> 0.98212425 | J29: =IF(B29=0,"",(C29+D29)/B29) -> 0.9 | K29: =IF(B29=0,"",E29/B29) -> 0.1 | L29: 9/10
A30: Router | B30: =COUNTIFS('Holdout R1'!$I$5:$I$182,"<>",'Holdout R1'!$B$5:$B$182,"Router") -> 10 | C30: =COUNTIFS('Holdout R1'!$I$5:$I$182,"Correct",'Holdout R1'!$B$5:$B$182,"Router") -> 10 | D30: =COUNTIFS('Holdout R1'!$I$5:$I$182,"Safe ask",'Holdout R1'!$B$5:$B$182,"Router") -> 0 | E30: =COUNTIFS('Holdout R1'!$I$5:$I$182,"Silent wrong",'Holdout R1'!$B$5:$B$182,"Router") -> 0 | F30: =COUNTIFS('Holdout R1'!$I$5:$I$182,"Missed",'Holdout R1'!$B$5:$B$182,"Router") -> 0 | G30: =IF(B30=0,"",C30/B30) -> 1 | H30: =IF(B30=0,"",(((C30/B30)+Summary!$B$3^2/(2*B30))-(Summary!$B$3*SQRT((C30/B30)*(1-(C30/B30))/B30+Summary!$B$3^2/(4*B30^2))))/(1+Summary!$B$3^2/B30)) -> 0.72245983 | I30: =IF(B30=0,"",(((C30/B30)+Summary!$B$3^2/(2*B30))+(Summary!$B$3*SQRT((C30/B30)*(1-(C30/B30))/B30+Summary!$B$3^2/(4*B30^2))))/(1+Summary!$B$3^2/B30)) -> 1 | J30: =IF(B30=0,"",(C30+D30)/B30) -> 1 | K30: =IF(B30=0,"",E30/B30) -> 0 | L30: 10/10
A31: All | B31: =COUNTIFS('Holdout R1'!$I$5:$I$182,"<>") -> 178 | C31: =COUNTIFS('Holdout R1'!$I$5:$I$182,"Correct") -> 112 | D31: =COUNTIFS('Holdout R1'!$I$5:$I$182,"Safe ask") -> 4 | E31: =COUNTIFS('Holdout R1'!$I$5:$I$182,"Silent wrong") -> 33 | F31: =COUNTIFS('Holdout R1'!$I$5:$I$182,"Missed") -> 29 | G31: =IF(B31=0,"",C31/B31) -> 0.62921348 | H31: =IF(B31=0,"",(((C31/B31)+Summary!$B$3^2/(2*B31))-(Summary!$B$3*SQRT((C31/B31)*(1-(C31/B31))/B31+Summary!$B$3^2/(4*B31^2))))/(1+Summary!$B$3^2/B31)) -> 0.55622527 | I31: =IF(B31=0,"",(((C31/B31)+Summary!$B$3^2/(2*B31))+(Summary!$B$3*SQRT((C31/B31)*(1-(C31/B31))/B31+Summary!$B$3^2/(4*B31^2))))/(1+Summary!$B$3^2/B31)) -> 0.69674214 | J31: =IF(B31=0,"",(C31+D31)/B31) -> 0.65168539 | K31: =IF(B31=0,"",E31/B31) -> 0.18539326 | L31: 90/135
A34: 3. Round 2 by statement type (entry bundles only)
A35: Bundle | B35: Rows | C35: Correct | D35: Safe ask | E35: Silent wrong | F35: Missed | G35: Strict accuracy | H35: 95% CI low | I35: 95% CI high | J35: Safe rate | K35: Silent-error rate | L35: Tests fully right
A36: Papa-style | B36: =COUNTIFS('Holdout R2 (final)'!$I$5:$I$170,"<>",'Holdout R2 (final)'!$C$5:$C$170,"Papa-style") -> 70 | C36: =COUNTIFS('Holdout R2 (final)'!$I$5:$I$170,"Correct",'Holdout R2 (final)'!$C$5:$C$170,"Papa-style") -> 53 | D36: =COUNTIFS('Holdout R2 (final)'!$I$5:$I$170,"Safe ask",'Holdout R2 (final)'!$C$5:$C$170,"Papa-style") -> 4 | E36: =COUNTIFS('Holdout R2 (final)'!$I$5:$I$170,"Silent wrong",'Holdout R2 (final)'!$C$5:$C$170,"Papa-style") -> 4 | F36: =COUNTIFS('Holdout R2 (final)'!$I$5:$I$170,"Missed",'Holdout R2 (final)'!$C$5:$C$170,"Papa-style") -> 9 | G36: =IF(B36=0,"",C36/B36) -> 0.75714286 | H36: =IF(B36=0,"",(((C36/B36)+Summary!$B$3^2/(2*B36))-(Summary!$B$3*SQRT((C36/B36)*(1-(C36/B36))/B36+Summary!$B$3^2/(4*B36^2))))/(1+Summary!$B$3^2/B36)) -> 0.64504739 | I36: =IF(B36=0,"",(((C36/B36)+Summary!$B$3^2/(2*B36))+(Summary!$B$3*SQRT((C36/B36)*(1-(C36/B36))/B36+Summary!$B$3^2/(4*B36^2))))/(1+Summary!$B$3^2/B36)) -> 0.84248267 | J36: =IF(B36=0,"",(C36+D36)/B36) -> 0.81428571 | K36: =IF(B36=0,"",E36/B36) -> 0.057142857
A37: Mixed | B37: =COUNTIFS('Holdout R2 (final)'!$I$5:$I$170,"<>",'Holdout R2 (final)'!$C$5:$C$170,"Mixed") -> 66 | C37: =COUNTIFS('Holdout R2 (final)'!$I$5:$I$170,"Correct",'Holdout R2 (final)'!$C$5:$C$170,"Mixed") -> 48 | D37: =COUNTIFS('Holdout R2 (final)'!$I$5:$I$170,"Safe ask",'Holdout R2 (final)'!$C$5:$C$170,"Mixed") -> 2 | E37: =COUNTIFS('Holdout R2 (final)'!$I$5:$I$170,"Silent wrong",'Holdout R2 (final)'!$C$5:$C$170,"Mixed") -> 6 | F37: =COUNTIFS('Holdout R2 (final)'!$I$5:$I$170,"Missed",'Holdout R2 (final)'!$C$5:$C$170,"Mixed") -> 10 | G37: =IF(B37=0,"",C37/B37) -> 0.72727273 | H37: =IF(B37=0,"",(((C37/B37)+Summary!$B$3^2/(2*B37))-(Summary!$B$3*SQRT((C37/B37)*(1-(C37/B37))/B37+Summary!$B$3^2/(4*B37^2))))/(1+Summary!$B$3^2/B37)) -> 0.60957546 | I37: =IF(B37=0,"",(((C37/B37)+Summary!$B$3^2/(2*B37))+(Summary!$B$3*SQRT((C37/B37)*(1-(C37/B37))/B37+Summary!$B$3^2/(4*B37^2))))/(1+Summary!$B$3^2/B37)) -> 0.81996797 | J37: =IF(B37=0,"",(C37+D37)/B37) -> 0.75757576 | K37: =IF(B37=0,"",E37/B37) -> 0.090909091
A38: Entry bundles | B38: =COUNTIFS('Holdout R2 (final)'!$I$5:$I$170,"<>",'Holdout R2 (final)'!$C$5:$C$170,"<>—") -> 136 | C38: =COUNTIFS('Holdout R2 (final)'!$I$5:$I$170,"Correct",'Holdout R2 (final)'!$C$5:$C$170,"<>—") -> 101 | D38: =COUNTIFS('Holdout R2 (final)'!$I$5:$I$170,"Safe ask",'Holdout R2 (final)'!$C$5:$C$170,"<>—") -> 6 | E38: =COUNTIFS('Holdout R2 (final)'!$I$5:$I$170,"Silent wrong",'Holdout R2 (final)'!$C$5:$C$170,"<>—") -> 10 | F38: =COUNTIFS('Holdout R2 (final)'!$I$5:$I$170,"Missed",'Holdout R2 (final)'!$C$5:$C$170,"<>—") -> 19 | G38: =IF(B38=0,"",C38/B38) -> 0.74264706 | H38: =IF(B38=0,"",(((C38/B38)+Summary!$B$3^2/(2*B38))-(Summary!$B$3*SQRT((C38/B38)*(1-(C38/B38))/B38+Summary!$B$3^2/(4*B38^2))))/(1+Summary!$B$3^2/B38)) -> 0.6632161 | I38: =IF(B38=0,"",(((C38/B38)+Summary!$B$3^2/(2*B38))+(Summary!$B$3*SQRT((C38/B38)*(1-(C38/B38))/B38+Summary!$B$3^2/(4*B38^2))))/(1+Summary!$B$3^2/B38)) -> 0.80874646 | J38: =IF(B38=0,"",(C38+D38)/B38) -> 0.78676471 | K38: =IF(B38=0,"",E38/B38) -> 0.073529412
A41: 4. Round 1 by statement type (entry bundles only)
A42: Bundle | B42: Rows | C42: Correct | D42: Safe ask | E42: Silent wrong | F42: Missed | G42: Strict accuracy | H42: 95% CI low | I42: 95% CI high | J42: Safe rate | K42: Silent-error rate | L42: Tests fully right
A43: Papa-style | B43: =COUNTIFS('Holdout R1'!$I$5:$I$182,"<>",'Holdout R1'!$C$5:$C$182,"Papa-style") -> 75 | C43: =COUNTIFS('Holdout R1'!$I$5:$I$182,"Correct",'Holdout R1'!$C$5:$C$182,"Papa-style") -> 43 | D43: =COUNTIFS('Holdout R1'!$I$5:$I$182,"Safe ask",'Holdout R1'!$C$5:$C$182,"Papa-style") -> 3 | E43: =COUNTIFS('Holdout R1'!$I$5:$I$182,"Silent wrong",'Holdout R1'!$C$5:$C$182,"Papa-style") -> 17 | F43: =COUNTIFS('Holdout R1'!$I$5:$I$182,"Missed",'Holdout R1'!$C$5:$C$182,"Papa-style") -> 12 | G43: =IF(B43=0,"",C43/B43) -> 0.57333333 | H43: =IF(B43=0,"",(((C43/B43)+Summary!$B$3^2/(2*B43))-(Summary!$B$3*SQRT((C43/B43)*(1-(C43/B43))/B43+Summary!$B$3^2/(4*B43^2))))/(1+Summary!$B$3^2/B43)) -> 0.46052589 | I43: =IF(B43=0,"",(((C43/B43)+Summary!$B$3^2/(2*B43))+(Summary!$B$3*SQRT((C43/B43)*(1-(C43/B43))/B43+Summary!$B$3^2/(4*B43^2))))/(1+Summary!$B$3^2/B43)) -> 0.67899437 | J43: =IF(B43=0,"",(C43+D43)/B43) -> 0.61333333 | K43: =IF(B43=0,"",E43/B43) -> 0.22666667
A44: Mixed | B44: =COUNTIFS('Holdout R1'!$I$5:$I$182,"<>",'Holdout R1'!$C$5:$C$182,"Mixed") -> 73 | C44: =COUNTIFS('Holdout R1'!$I$5:$I$182,"Correct",'Holdout R1'!$C$5:$C$182,"Mixed") -> 43 | D44: =COUNTIFS('Holdout R1'!$I$5:$I$182,"Safe ask",'Holdout R1'!$C$5:$C$182,"Mixed") -> 1 | E44: =COUNTIFS('Holdout R1'!$I$5:$I$182,"Silent wrong",'Holdout R1'!$C$5:$C$182,"Mixed") -> 12 | F44: =COUNTIFS('Holdout R1'!$I$5:$I$182,"Missed",'Holdout R1'!$C$5:$C$182,"Mixed") -> 17 | G44: =IF(B44=0,"",C44/B44) -> 0.5890411 | H44: =IF(B44=0,"",(((C44/B44)+Summary!$B$3^2/(2*B44))-(Summary!$B$3*SQRT((C44/B44)*(1-(C44/B44))/B44+Summary!$B$3^2/(4*B44^2))))/(1+Summary!$B$3^2/B44)) -> 0.47449015 | I44: =IF(B44=0,"",(((C44/B44)+Summary!$B$3^2/(2*B44))+(Summary!$B$3*SQRT((C44/B44)*(1-(C44/B44))/B44+Summary!$B$3^2/(4*B44^2))))/(1+Summary!$B$3^2/B44)) -> 0.69468904 | J44: =IF(B44=0,"",(C44+D44)/B44) -> 0.60273973 | K44: =IF(B44=0,"",E44/B44) -> 0.16438356
A45: Entry bundles | B45: =COUNTIFS('Holdout R1'!$I$5:$I$182,"<>",'Holdout R1'!$C$5:$C$182,"<>—") -> 148 | C45: =COUNTIFS('Holdout R1'!$I$5:$I$182,"Correct",'Holdout R1'!$C$5:$C$182,"<>—") -> 86 | D45: =COUNTIFS('Holdout R1'!$I$5:$I$182,"Safe ask",'Holdout R1'!$C$5:$C$182,"<>—") -> 4 | E45: =COUNTIFS('Holdout R1'!$I$5:$I$182,"Silent wrong",'Holdout R1'!$C$5:$C$182,"<>—") -> 29 | F45: =COUNTIFS('Holdout R1'!$I$5:$I$182,"Missed",'Holdout R1'!$C$5:$C$182,"<>—") -> 29 | G45: =IF(B45=0,"",C45/B45) -> 0.58108108 | H45: =IF(B45=0,"",(((C45/B45)+Summary!$B$3^2/(2*B45))-(Summary!$B$3*SQRT((C45/B45)*(1-(C45/B45))/B45+Summary!$B$3^2/(4*B45^2))))/(1+Summary!$B$3^2/B45)) -> 0.50052562 | I45: =IF(B45=0,"",(((C45/B45)+Summary!$B$3^2/(2*B45))+(Summary!$B$3*SQRT((C45/B45)*(1-(C45/B45))/B45+Summary!$B$3^2/(4*B45^2))))/(1+Summary!$B$3^2/B45)) -> 0.65753383 | J45: =IF(B45=0,"",(C45+D45)/B45) -> 0.60810811 | K45: =IF(B45=0,"",E45/B45) -> 0.19594595
A48: How to read this
A49: • Round 2 is the headline result on unseen data: it was written after the round-1 fixes and run once, with no fix after it.
...

Sheet Holdout R2 (final)
A1: Holdout round 2 (FINAL) — 135 new unseen statements (run 2026-10-08 16:51, Hinglish)
A2: Same design as round 1, new statements, written after the round-1 fixes and locked 16:49. Run ONCE; no fix was made after this run, so these are the final numbers on unseen data. Before the run the user simplified 5 statements (EMP-04, EMP-07, EMP-08, SUP-07, PUR-01).
A3: Same scorer and rules as round 1 and the dev bundles. A correctly asked question on an ASK test counts as Correct. Debatable rows kept as scored: RPT-03 'pichle paanch din' (start 3 Oct vs 4 Oct), CUS-06 quantity 0 vs 1.
A4: Test ID | B4: Bundle | C4: Statement type | D4: Event # | E4: Statement (Hinglish) | F4: Expected outcome | G4: Expected entry / route | H4: Actual (system output) | I4: Result | J4: Remark (scorer)
A5: F2-EMP-01 | B5: Employee | C5: Papa-style | D5: 1 | E5: Naresh beldar ki aaj ki 550 mazdoori chuka di | F5: ENTRY | G5: employee_transaction(employee_name=Naresh, transaction_type=payment, amount=550, date=T) | H5: employee_transaction(note=mazdoori chuka di, amount=550.0, employee_name=Naresh beldar, transaction_date=2026-10-08, transaction_type=payment) | I5: Correct
A6: F2-EMP-02 | B6: Employee | C6: Papa-style | D6: 1 | E6: Sohan aaj site pe nahi aaya, beemar hai | F6: ENTRY | G6: attendance(employee_name=Sohan, attendance=absent, date=T) | H6: attendance(note=beemar hai, driving=absent, attendance=absent, employee_name=Sohan, attendance_date=2026-10-08) | I6: Correct
A7: F2-EMP-03 | B7: Employee | C7: Papa-style | D7: 1 | E7: Ram ne gudam mein darwaze chhaante, 700 bante hain | F7: ENTRY | G7: employee_transaction(employee_name=Ram, transaction_type=work, amount=700, date=T) | H7: (no entry) | I7: Missed | J7: record_employee_transaction: no entry, no question (route=accounting)
A8: F2-EMP-04 | B8: Employee | C8: Papa-style | D8: 1 | E8: Kitanu aaj kaam pe aaya, tractor bhi usi ne chalaya | F8: ENTRY | G8: attendance(employee_name=Kitanu, attendance=P, driving=P, date=T) | H8: attendance(driving=P, attendance=P, employee_name=Kitanu, attendance_date=2026-10-08) | I8: Correct
A9: F2-EMP-05 | B9: Employee | C9: Papa-style | D9: 1 | E9: Pappu ko kal 300 aur aaj 400 diye | F9: ENTRY | G9: employee_transaction(employee_name=Pappu, transaction_type=payment, amount=300, date=T-1) | H9: employee_transaction(amount=300.0, employee_name=Pappu, transaction_date=2026-10-07, transaction_type=payment); employee_transaction(amount=400.0, employee_name=Pappu, transaction_date=2026-10-08, transaction_type=payment) | I9: Correct
A10: F2-EMP-05 | B10: Employee | C10: Papa-style | D10: 2 | E10: Pappu ko kal 300 aur aaj 400 diye | F10: ENTRY | G10: employee_transaction(employee_name=Pappu, transaction_type=payment, amount=400, date=T) | H10: ″ | I10: Correct
A11: F2-EMP-06 | B11: Employee | C11: Papa-style | D11: 1 | E11: sohan ko saade teen sau thama diye dopahar mein | F11: ENTRY | G11: employee_transaction(employee_name=Sohan, transaction_type=payment, amount=350, date=T) | H11: employee_transaction(amount=350.0, employee_name=Sohan, transaction_date=2026-10-08, transaction_type=payment) | I11: Correct
A12: F2-EMP-07 | B12: Employee | C12: Papa-style | D12: 1 | E12: Naresh aaj aaya aur 600 le gaya | F12: ENTRY | G12: attendance(employee_name=Naresh, attendance=P, date=T) | H12: attendance(driving=absent, attendance=P, employee_name=Naresh, attendance_date=2026-10-08) | I12: Correct | J12: record_employee_transaction: no entry, no question (route=accounting)
A13: F2-EMP-07 | B13: Employee | C13: Papa-style | D13: 2 | E13: Naresh aaj aaya aur 600 le gaya | F13: ENTRY | G13: employee_transaction(employee_name=Naresh, transaction_type=payment, amount=600, date=T) | H13: ″ | I13: Missed
A14: F2-EMP-08 | B14: Employee | C14: Papa-style | D14: 1 | E14: Pappu ko agle hafte 500 denge | F14: NO-ENTRY | G14: (no entry) | H14: (no entry) | I14: Correct
A15: F2-EMP-09 | B15: Employee | C15: Mixed | D15: 1 | E15: Naresh ne aaj gudam pe chaukhat saaf ki, 500 banta hai | F15: ENTRY | G15: employee_transaction(employee_name=Naresh, transaction_type=work, amount=500, date=T) | H15: employee_transaction(note=gudam pe chaukhat saaf ki, amount=500.0, employee_name=Naresh, transaction_date=2026-10-08, transaction_type=work) | I15: Correct
A16: F2-EMP-10 | B16: Employee | C16: Mixed | D16: 1 | E16: Ram lunch ke baad nikal gaya aaj, aadha din hi raha | F16: ENTRY | G16: attendance(employee_name=Ram, attendance=half, date=T) | H16: attendance(driving=absent, attendance=half, employee_name=Ram, attendance_date=2026-10-08) | I16: Correct
A17: F2-EMP-11 | B17: Employee | C17: Mixed | D17: 1 | E17: Pappu ko 1000 advance de diye shaadi ke liye | F17: ENTRY | G17: employee_transaction(employee_name=Pappu, transaction_type=payment, amount=1000, date=T) | H17: employee_transaction(note=advance de diye shaadi ke liye, amount=1000.0, employee_name=Pappu, transaction_date=2026-10-08, transaction_type=payment) | I17: Correct
A18: F2-EMP-12 | B18: Employee | C18: Mixed | D18: 1 | E18: Kitanu ko aaj 250 kharche ke diye | F18: ENTRY | G18: employee_transaction(employee_name=Kitanu, transaction_type=payment, amount=250, date=T) | H18: employee_transaction(note=kharche ke diye, amount=250.0, employee_name=Kitanu, transaction_date=2026-10-08, transaction_type=payment) | I18: Correct
A19: F2-EMP-13 | B19: Employee | C19: Mixed | D19: 1 | E19: Naresh ki aaj chhutti rahi | F19: ENTRY | G19: attendance(employee_name=Naresh, attendance=absent, date=T) | H19: attendance(note=chhutti rahi, driving=absent, attendance=absent, employee_name=Naresh, attendance_date=2026-10-08) | I19: Correct
A20: F2-EMP-14 | B20: Employee | C20: Mixed | D20: 1 | E20: pappu kal aadha din aaya tha, aaj poora | F20: ENTRY | G20: attendance(employee_name=Pappu, attendance=half, date=T-1) | H20: attendance(driving=absent, attendance=half, employee_name=Pappu, attendance_date=2026-10-07); attendance(driving=absent, attendance=P, employee_name=Pappu, attendance_date=2026-10-08) | I20: Correct
A21: F2-EMP-14 | B21: Employee | C21: Mixed | D21: 2 | E21: pappu kal aadha din aaya tha, aaj poora | F21: ENTRY | G21: attendance(employee_name=Pappu, attendance=P, date=T) | H21: ″ | I21: Correct
A22: F2-EMP-15 | B22: Employee | C22: Mixed | D22: 1 | E22: Naresh ko kuch paise de diye | F22: ASK | G22: employee_transaction(employee_name=Naresh, transaction_type=payment, date=T) | H22: (no entry) | asked: missing_argument | I22: Correct | J22: record_employee_transaction: asked missing_argument:record_employee_transaction ['amount']
A23: F2-CUS-01 | B23: Customer | C23: Papa-style | D23: 1 | E23: Dalbir ko 12 purani khidkiyan 6000 mein bechi | F23: ENTRY | G23: sale_transaction(customer_name=Dalbir, item_name=khidki, quantity=12, amount=6000, date=T) | H23: (no entry) | asked: material_movement, material_movement, missing_argument | I23: Safe ask | J23: record_sale_transaction: asked missing_argument:record_sale_transaction ['amount']
A24: F2-CUS-02 | B24: Customer | C24: Papa-style | D24: 1 | E24: Kuldeep ji ne 4500 bheje PhonePe se | F24: ENTRY | G24: sale_payment(customer_name=Kuldeep ji, amount=4500, date=T) | H24: sale_payment(amount=4500.0, payment_date=2026-10-08, customer_name=Kuldeep ji) | I24: Correct
A25: F2-CUS-03 | B25: Customer | C25: Papa-style | D25: 1 | E25: Gudam se 2000 eent Sharma ji ke plot pe gayi, 6 ka rate | F25: ENTRY | G25: sale_transaction(customer_name=Sharma ji, item_name=eent, quantity=2000, rate=6, amount=12000, source=gudam, date=T) | H25: sale_transaction(rate=6.0, unit=piece, amount=12000.0, source=Gudam, quantity=2000.0, item_name=eent, sale_date=2026-10-08, customer_name=Sharma ji, destination_name=plot, update_inventory=True) | I25: Correct
A26: F2-CUS-04 | B26: Customer | C26: Papa-style | D26: 1 | E26: Dalbir pe pehle ka 3500 nikalta hai | F26: ENTRY | G26: opening_balance(party_name=Dalbir, amount=3500, direction=lena) | H26: (no entry) | asked: correction | I26: Missed | J26: record_opening_balance: asked correction:
A27: F2-CUS-05 | B27: Customer | C27: Papa-style | D27: 1 | E27: Suresh Traders 5 shahteer le gaye 10000 ke, 4000 de gaye | F27: ENTRY | G27: sale_transaction(customer_name=Suresh Traders, item_name=shahteer, quantity=5, amount=10000, date=T) | H27: sale_transaction(amount=10000.0, quantity=5.0, item_name=shahteer, sale_date=2026-10-08, customer_name=Suresh Traders, supplier_name=Suresh Traders, update_inventory=True); sale_payment(amount=4000.0, payment_date=2026-10-08, customer_name=Suresh Traders) | I27: Correct
A28: F2-CUS-05 | B28: Customer | C28: Papa-style | D28: 2 | E28: Suresh Traders 5 shahteer le gaye 10000 ke, 4000 de gaye | F28: ENTRY | G28: sale_payment(customer_name=Suresh Traders, amount=4000, date=T) | H28: ″ | I28: Correct
A29: F2-CUS-06 | B29: Customer | C29: Papa-style | D29: 1 | E29: kuldeep ji ko dhai hazaar ki ek purani almari di | F29: ENTRY | G29: sale_transaction(customer_name=Kuldeep ji, item_name=almari, quantity=1, amount=2500, date=T) | H29: sale_transaction(amount=2500.0, item_name=purani almari, sale_date=2026-10-08, customer_name=kuldeep ji, update_inventory=True) | asked: material_movement, material_movement | I29: Silent wrong | J29: record_sale_transaction: quantity 0.0≠1
A30: F2-CUS-07 | B30: Customer | C30: Papa-style | D30: 1 | E30: Dalbir 300 eent le gaya | F30: ASK | G30: sale_transaction(customer_name=Dalbir, item_name=eent, quantity=300, date=T) | H30: (no entry) | asked: material_movement, material_movement | I30: Missed | J30: record_sale_transaction: no entry, no question (route=accounting)
A31: F2-CUS-08 | B31: Customer | C31: Papa-style | D31: 1 | E31: Sharma ji ne bola hai parso tak 5000 pahuncha denge | F31: NO-ENTRY | G31: (no entry) | H31: (no entry) | I31: Correct
A32: F2-CUS-09 | B32: Customer | C32: Mixed | D32: 1 | E32: Kuldeep ji ko 20 balli 6000 mein di, gudam se | F32: ENTRY | G32: sale_transaction(customer_name=Kuldeep ji, item_name=balli, quantity=20, amount=6000, source=gudam, date=T) | H32: (no entry) | asked: material_movement | I32: Missed | J32: record_sale_transaction: no entry, no question (route=accounting)
A33: F2-CUS-10 | B33: Customer | C33: Mixed | D33: 1 | E33: Dalbir ne purane 1500 de diye | F33: ENTRY | G33: sale_payment(customer_name=Dalbir, amount=1500, date=T) | H33: sale_payment(note=purane, amount=1500.0, payment_date=2026-10-08, customer_name=Dalbir) | I33: Correct
A34: F2-CUS-11 | B34: Customer | C34: Mixed | D34: 1 | E34: Sharma ji ko 4 girder 16000 ke diye, 10000 aaye | F34: ENTRY | G34: sale_transaction(customer_name=Sharma ji, item_name=girder, quantity=4, amount=16000, date=T) | H34: sale_transaction(amount=16000.0, quantity=4.0, item_name=girder, sale_date=2026-10-08, customer_name=Sharma ji, supplier_name=Sharma ji, update_inventory=True); sale_payment(amount=10000.0, payment_date=2026-10-08, customer_name=Sharma ji) | I34: Correct
A35: F2-CUS-11 | B35: Customer | C35: Mixed | D35: 2 | E35: Sharma ji ko 4 girder 16000 ke diye, 10000 aaye | F35: ENTRY | G35: sale_payment(customer_name=Sharma ji, amount=10000, date=T) | H35: ″ | I35: Correct
A36: F2-CUS-12 | B36: Customer | C36: Mixed | D36: 1 | E36: Kuldeep ji ka 2000 aaya | F36: ENTRY | G36: sale_payment(customer_name=Kuldeep ji, amount=2000, date=T) | H36: sale_payment(amount=2000.0, payment_date=2026-10-08, customer_name=Kuldeep ji) | I36: Correct
A37: F2-CUS-13 | B37: Customer | C37: Mixed | D37: 1 | E37: Satbir paanch sau eent le gaya teen hazaar ki | F37: ENTRY | G37: sale_transaction(customer_name=Satbir, item_name=eent, quantity=500, amount=3000, date=T) | H37: (no entry) | asked: material_movement, material_movement | I37: Missed | J37: record_sale_transaction: no entry, no question (route=accounting)
A38: F2-CUS-14 | B38: Customer | C38: Mixed | D38: 1 | E38: dalbir ko sava sau eent saade paanch ke rate se | F38: ENTRY | G38: sale_transaction(customer_name=Dalbir, item_name=eent, quantity=125, rate=5.5, amount=687.5, date=T) | H38: sale_transaction(rate=5.0, amount=3750.0, quantity=750.0, item_name=eent, sale_date=2026-10-08, customer_name=Dalbir, update_inventory=True) | asked: material_movement, material_movement | I38: Silent wrong | J38: record_sale_transaction: amount 3750.0≠687.5; quantity 750.0≠125; rate 5.0≠5.5
A39: F2-CUS-15 | B39: Customer | C39: Mixed | D39: 1 | E39: Dalbir se 1000 aaye, aur Sharma ji 300 eent 1800 mein le gaye | F39: ENTRY | G39: sale_payment(customer_name=Dalbir, amount=1000, date=T) | H39: sale_payment(amount=1000.0, payment_date=2026-10-08, customer_name=Dalbir); sale_transaction(amount=1800.0, quantity=300.0, item_name=eent, sale_date=2026-10-08, customer_name=Sharma ji, update_inventory=True) | asked: material_movement | I39: Correct
A40: F2-CUS-15 | B40: Customer | C40: Mixed | D40: 2 | E40: Dalbir se 1000 aaye, aur Sharma ji 300 eent 1800 mein le gaye | F40: ENTRY | G40: sale_transaction(customer_name=Sharma ji, item_name=eent, quantity=300, amount=1800, date=T) | H40: ″ | I40: Correct
...

Sheet Holdout R1
A1: Holdout round 1 — 135 unseen statements (run 2026-10-08 14:40, Hinglish)
A2: Written by the assistant in the owner's business style, locked by the user before the run, never seen by the prompts or the dev test sets (difflib similarity ≤ 0.69). 7 entry bundles × 15 (8 papa-style + 7 mixed) + Report / Correction / Router × 10.
A3: This round was USED for fixing afterwards (7 fix groups, see Changelog), so after the fixes it is no longer unseen. Scorer fix after the run: STK-02 / STK-12 driver_name removed (the movement tool has no driver field).
A4: Test ID | B4: Bundle | C4: Statement type | D4: Event # | E4: Statement (Hinglish) | F4: Expected outcome | G4: Expected entry / route | H4: Actual (system output) | I4: Result | J4: Remark (scorer)
A5: FIN-EMP-01 | B5: Employee | C5: Papa-style | D5: 1 | E5: Bhupender ko aaj ki dihadi 600 de di | F5: ENTRY | G5: employee_transaction(employee_name=Bhupender, transaction_type=payment, amount=600, date=T) | H5: employee_transaction(note=aaj ki dihadi, amount=600.0, employee_name=Bhupender, transaction_date=2026-10-08, transaction_type=payment) | I5: Correct
A6: FIN-EMP-02 | B6: Employee | C6: Papa-style | D6: 1 | E6: Kitanu aaj trolley lekar do chakkar Kalanaur gaya | F6: ENTRY | G6: attendance(employee_name=Kitanu, attendance=P, driving=P, date=T) | H6: (no entry) | asked: material_movement, material_movement | I6: Missed | J6: record_attendance: no entry, no question (route=accounting)
A7: FIN-EMP-03 | B7: Employee | C7: Papa-style | D7: 1 | E7: Sohan ne Dhani wali site pe chaukhat nikalne ka 800 ka kaam kiya | F7: ENTRY | G7: employee_transaction(employee_name=Sohan, transaction_type=work, amount=800, date=T) | H7: employee_transaction(note=Dhani wali site pe chaukhat nikalne ka, amount=800.0, employee_name=Sohan, transaction_date=2026-10-08, transaction_type=work) | I7: Correct
A8: FIN-EMP-04 | B8: Employee | C8: Papa-style | D8: 1 | E8: Ram aaj dopahar baad aaya, aadha din | F8: ENTRY | G8: attendance(employee_name=Ram, attendance=half, date=T) | H8: (no entry) | asked: missing_argument | I8: Safe ask | J8: record_attendance: asked missing_argument:record_employee_transaction ['amount']
A9: FIN-EMP-05 | B9: Employee | C9: Papa-style | D9: 1 | E9: Mahavir mistri ko 2000 advance diye, agle hafte se kaam pe aayega | F9: ENTRY | G9: employee_transaction(employee_name=Mahavir, transaction_type=payment, amount=2000, date=T) | H9: employee_transaction(note=advance, amount=2000.0, employee_name=Mahavir mistri, transaction_date=2026-10-08, transaction_type=payment) | I9: Correct
A10: FIN-EMP-06 | B10: Employee | C10: Papa-style | D10: 1 | E10: Sohan aur Ram dono ne aaj girder katai ki, 500-500 banta hai | F10: ENTRY | G10: employee_transaction(employee_name=Sohan, transaction_type=work, amount=500, date=T) | H10: employee_transaction(amount=500.0, employee_name=Sohan, transaction_date=2026-10-08, transaction_type=payment); employee_transaction(amount=500.0, employee_name=Ram, transaction_date=2026-10-08, transaction_type=payment) | I10: Silent wrong | J10: record_employee_transaction: transaction_type payment≠work · record_employee_transaction: transaction_type payment≠work
A11: FIN-EMP-06 | B11: Employee | C11: Papa-style | D11: 2 | E11: Sohan aur Ram dono ne aaj girder katai ki, 500-500 banta hai | F11: ENTRY | G11: employee_transaction(employee_name=Ram, transaction_type=work, amount=500, date=T) | H11: ″ | I11: Silent wrong
A12: FIN-EMP-07 | B12: Employee | C12: Papa-style | D12: 1 | E12: Kitanu kal chutti pe tha | F12: ENTRY | G12: attendance(employee_name=Kitanu, attendance=absent, date=T-1) | H12: attendance(note=chutti pe tha, driving=absent, attendance=absent, employee_name=Kitanu, attendance_date=2026-10-07) | I12: Correct
A13: FIN-EMP-08 | B13: Employee | C13: Papa-style | D13: 1 | E13: Bhupender ke purane hisab ke 1500 dene baaki hain | F13: ENTRY | G13: opening_balance(party_name=Bhupender, amount=1500, direction=dena) | H13: opening_balance(note=purane hisab ke dene baaki hain, amount=1500.0, direction=dena, as_of_date=2026-10-08, party_name=Bhupender, party_type=employee) | I13: Correct
A14: FIN-EMP-09 | B14: Employee | C14: Mixed | D14: 1 | E14: Sohan ko 300 kharchi di | F14: ENTRY | G14: employee_transaction(employee_name=Sohan, transaction_type=payment, amount=300, date=T) | H14: employee_transaction(note=kharchi di, amount=300.0, employee_name=Sohan, transaction_date=2026-10-08, transaction_type=payment) | I14: Correct
A15: FIN-EMP-10 | B15: Employee | C15: Mixed | D15: 1 | E15: Ram subah saat baje hi pahunch gaya tha aaj | F15: ENTRY | G15: attendance(employee_name=Ram, attendance=P, date=T) | H15: attendance(note=subah saat baje hi pahunch gaya tha, driving=absent, attendance=P, employee_name=Ram, attendance_date=2026-10-08) | I15: Correct
A16: FIN-EMP-11 | B16: Employee | C16: Mixed | D16: 1 | E16: ram ko kal 5 sau diye the uske baad aaj 2 sau aur | F16: ENTRY | G16: employee_transaction(employee_name=Ram, transaction_type=payment, amount=500, date=T-1) | H16: employee_transaction(amount=500.0, employee_name=Ram, transaction_date=2026-10-07, transaction_type=payment); employee_transaction(amount=200.0, employee_name=Ram, transaction_date=2026-10-08, transaction_type=payment) | I16: Correct
A17: FIN-EMP-11 | B17: Employee | C17: Mixed | D17: 2 | E17: ram ko kal 5 sau diye the uske baad aaj 2 sau aur | F17: ENTRY | G17: employee_transaction(employee_name=Ram, transaction_type=payment, amount=200, date=T) | H17: ″ | I17: Correct
A18: FIN-EMP-12 | B18: Employee | C18: Mixed | D18: 1 | E18: Mahavir ka number 9812233445 hai, mistri hai wo | F18: ENTRY | G18: manage_employee(employee_name=Mahavir) | H18: manage_employee(role=mistri, phone=9812233445, employee_name=Mahavir) | I18: Correct
A19: FIN-EMP-13 | B19: Employee | C19: Mixed | D19: 1 | E19: Mahavir ka hisab chuka diya | F19: ASK | G19: employee_transaction(employee_name=Mahavir, transaction_type=payment, date=T) | H19: (no entry) | asked: missing_argument | I19: Correct | J19: record_employee_transaction: asked missing_argument:record_employee_transaction ['amount']
A20: FIN-EMP-14 | B20: Employee | C20: Mixed | D20: 1 | E20: Ram aaj aaya, 650 ka kaam kiya aur 400 le gaya | F20: ENTRY | G20: attendance(employee_name=Ram, attendance=P, date=T) | H20: attendance(driving=absent, attendance=P, employee_name=Ram, attendance_date=2026-10-08); employee_transaction(amount=650.0, employee_name=Ram, transaction_date=2026-10-08, transaction_type=work); employee_transaction(amount=400.0, employee_name=Ram, transaction_date=2026-10-08, transaction_type=payment) | I20: Correct
A21: FIN-EMP-14 | B21: Employee | C21: Mixed | D21: 2 | E21: Ram aaj aaya, 650 ka kaam kiya aur 400 le gaya | F21: ENTRY | G21: employee_transaction(employee_name=Ram, transaction_type=work, amount=650, date=T) | H21: ″ | I21: Correct
A22: FIN-EMP-14 | B22: Employee | C22: Mixed | D22: 3 | E22: Ram aaj aaya, 650 ka kaam kiya aur 400 le gaya | F22: ENTRY | G22: employee_transaction(employee_name=Ram, transaction_type=payment, amount=400, date=T) | H22: ″ | I22: Correct
